[2024-12-17T23:59:53.241+0000] {local_task_job_runner.py:123} INFO - ::group::Pre task execution logs
[2024-12-17T23:59:53.266+0000] {taskinstance.py:2613} INFO - Dependencies all met for dep_context=non-requeueable deps ti=<TaskInstance: instacart_etl.etl_dim_department manual__2024-12-17T23:59:49.335841+00:00 [queued]>
[2024-12-17T23:59:53.278+0000] {taskinstance.py:2613} INFO - Dependencies all met for dep_context=requeueable deps ti=<TaskInstance: instacart_etl.etl_dim_department manual__2024-12-17T23:59:49.335841+00:00 [queued]>
[2024-12-17T23:59:53.278+0000] {taskinstance.py:2866} INFO - Starting attempt 1 of 1
[2024-12-17T23:59:53.315+0000] {taskinstance.py:2889} INFO - Executing <Task(PythonOperator): etl_dim_department> on 2024-12-17 23:59:49.335841+00:00
[2024-12-17T23:59:53.331+0000] {logging_mixin.py:190} WARNING - /home/***/.local/lib/python3.12/site-packages/***/task/task_runner/standard_task_runner.py:70 DeprecationWarning: This process (pid=2941) is multi-threaded, use of fork() may lead to deadlocks in the child.
[2024-12-17T23:59:53.332+0000] {standard_task_runner.py:72} INFO - Started process 2949 to run task
[2024-12-17T23:59:53.330+0000] {standard_task_runner.py:104} INFO - Running: ['***', 'tasks', 'run', 'instacart_etl', 'etl_dim_department', 'manual__2024-12-17T23:59:49.335841+00:00', '--job-id', '117', '--raw', '--subdir', 'DAGS_FOLDER/instacart_etl_dag.py', '--cfg-path', '/tmp/tmpdjr2aidy']
[2024-12-17T23:59:53.333+0000] {standard_task_runner.py:105} INFO - Job 117: Subtask etl_dim_department
[2024-12-17T23:59:53.424+0000] {task_command.py:467} INFO - Running <TaskInstance: instacart_etl.etl_dim_department manual__2024-12-17T23:59:49.335841+00:00 [running]> on host 0040d02929fc
[2024-12-17T23:59:53.852+0000] {taskinstance.py:3132} INFO - Exporting env vars: AIRFLOW_CTX_DAG_OWNER='***' AIRFLOW_CTX_DAG_ID='instacart_etl' AIRFLOW_CTX_TASK_ID='etl_dim_department' AIRFLOW_CTX_EXECUTION_DATE='2024-12-17T23:59:49.335841+00:00' AIRFLOW_CTX_TRY_NUMBER='1' AIRFLOW_CTX_DAG_RUN_ID='manual__2024-12-17T23:59:49.335841+00:00'
[2024-12-17T23:59:53.856+0000] {taskinstance.py:731} INFO - ::endgroup::
[2024-12-17T23:59:54.116+0000] {taskinstance.py:3311} ERROR - Task failed with exception
Traceback (most recent call last):
  File "/home/airflow/.local/lib/python3.12/site-packages/airflow/models/taskinstance.py", line 767, in _execute_task
    result = _execute_callable(context=context, **execute_callable_kwargs)
             ^^^^^^^^^^^^^^^^^^^^^^^^^^^^^^^^^^^^^^^^^^^^^^^^^^^^^^^^^^^^^
  File "/home/airflow/.local/lib/python3.12/site-packages/airflow/models/taskinstance.py", line 733, in _execute_callable
    return ExecutionCallableRunner(
           ^^^^^^^^^^^^^^^^^^^^^^^^
  File "/home/airflow/.local/lib/python3.12/site-packages/airflow/utils/operator_helpers.py", line 252, in run
    return self.func(*args, **kwargs)
           ^^^^^^^^^^^^^^^^^^^^^^^^^^
  File "/home/airflow/.local/lib/python3.12/site-packages/airflow/models/baseoperator.py", line 417, in wrapper
    return func(self, *args, **kwargs)
           ^^^^^^^^^^^^^^^^^^^^^^^^^^^
  File "/home/airflow/.local/lib/python3.12/site-packages/airflow/operators/python.py", line 238, in execute
    return_value = self.execute_callable()
                   ^^^^^^^^^^^^^^^^^^^^^^^
  File "/home/airflow/.local/lib/python3.12/site-packages/airflow/operators/python.py", line 256, in execute_callable
    return runner.run(*self.op_args, **self.op_kwargs)
           ^^^^^^^^^^^^^^^^^^^^^^^^^^^^^^^^^^^^^^^^^^^
  File "/home/airflow/.local/lib/python3.12/site-packages/airflow/utils/operator_helpers.py", line 252, in run
    return self.func(*args, **kwargs)
           ^^^^^^^^^^^^^^^^^^^^^^^^^^
  File "/opt/airflow/dags/instacart_etl_dag.py", line 88, in etl_dim_table
    cursor.executemany(f"""
pyodbc.ProgrammingError: The second parameter to executemany must not be empty.
[2024-12-17T23:59:54.145+0000] {taskinstance.py:1225} INFO - Marking task as FAILED. dag_id=instacart_etl, task_id=etl_dim_department, run_id=manual__2024-12-17T23:59:49.335841+00:00, execution_date=20241217T235949, start_date=20241217T235953, end_date=20241217T235954
[2024-12-17T23:59:54.167+0000] {taskinstance.py:340} INFO - ::group::Post task execution logs
[2024-12-17T23:59:54.168+0000] {standard_task_runner.py:124} ERROR - Failed to execute job 117 for task etl_dim_department (The second parameter to executemany must not be empty.; 2949)
Traceback (most recent call last):
  File "/home/airflow/.local/lib/python3.12/site-packages/airflow/task/task_runner/standard_task_runner.py", line 117, in _start_by_fork
    ret = args.func(args, dag=self.dag)
          ^^^^^^^^^^^^^^^^^^^^^^^^^^^^^
  File "/home/airflow/.local/lib/python3.12/site-packages/airflow/cli/cli_config.py", line 49, in command
    return func(*args, **kwargs)
           ^^^^^^^^^^^^^^^^^^^^^
  File "/home/airflow/.local/lib/python3.12/site-packages/airflow/utils/cli.py", line 116, in wrapper
    return f(*args, **kwargs)
           ^^^^^^^^^^^^^^^^^^
  File "/home/airflow/.local/lib/python3.12/site-packages/airflow/cli/commands/task_command.py", line 483, in task_run
    task_return_code = _run_task_by_selected_method(args, _dag, ti)
                       ^^^^^^^^^^^^^^^^^^^^^^^^^^^^^^^^^^^^^^^^^^^^
  File "/home/airflow/.local/lib/python3.12/site-packages/airflow/cli/commands/task_command.py", line 256, in _run_task_by_selected_method
    return _run_raw_task(args, ti)
           ^^^^^^^^^^^^^^^^^^^^^^^
  File "/home/airflow/.local/lib/python3.12/site-packages/airflow/cli/commands/task_command.py", line 341, in _run_raw_task
    return ti._run_raw_task(
           ^^^^^^^^^^^^^^^^^
  File "/home/airflow/.local/lib/python3.12/site-packages/airflow/utils/session.py", line 97, in wrapper
    return func(*args, session=session, **kwargs)
           ^^^^^^^^^^^^^^^^^^^^^^^^^^^^^^^^^^^^^^
  File "/home/airflow/.local/lib/python3.12/site-packages/airflow/models/taskinstance.py", line 3005, in _run_raw_task
    return _run_raw_task(
           ^^^^^^^^^^^^^^
  File "/home/airflow/.local/lib/python3.12/site-packages/airflow/models/taskinstance.py", line 273, in _run_raw_task
    TaskInstance._execute_task_with_callbacks(
  File "/home/airflow/.local/lib/python3.12/site-packages/airflow/models/taskinstance.py", line 3159, in _execute_task_with_callbacks
    result = self._execute_task(context, task_orig)
             ^^^^^^^^^^^^^^^^^^^^^^^^^^^^^^^^^^^^^^
  File "/home/airflow/.local/lib/python3.12/site-packages/airflow/models/taskinstance.py", line 3183, in _execute_task
    return _execute_task(self, context, task_orig)
           ^^^^^^^^^^^^^^^^^^^^^^^^^^^^^^^^^^^^^^^
  File "/home/airflow/.local/lib/python3.12/site-packages/airflow/models/taskinstance.py", line 767, in _execute_task
    result = _execute_callable(context=context, **execute_callable_kwargs)
             ^^^^^^^^^^^^^^^^^^^^^^^^^^^^^^^^^^^^^^^^^^^^^^^^^^^^^^^^^^^^^
  File "/home/airflow/.local/lib/python3.12/site-packages/airflow/models/taskinstance.py", line 733, in _execute_callable
    return ExecutionCallableRunner(
           ^^^^^^^^^^^^^^^^^^^^^^^^
  File "/home/airflow/.local/lib/python3.12/site-packages/airflow/utils/operator_helpers.py", line 252, in run
    return self.func(*args, **kwargs)
           ^^^^^^^^^^^^^^^^^^^^^^^^^^
  File "/home/airflow/.local/lib/python3.12/site-packages/airflow/models/baseoperator.py", line 417, in wrapper
    return func(self, *args, **kwargs)
           ^^^^^^^^^^^^^^^^^^^^^^^^^^^
  File "/home/airflow/.local/lib/python3.12/site-packages/airflow/operators/python.py", line 238, in execute
    return_value = self.execute_callable()
                   ^^^^^^^^^^^^^^^^^^^^^^^
  File "/home/airflow/.local/lib/python3.12/site-packages/airflow/operators/python.py", line 256, in execute_callable
    return runner.run(*self.op_args, **self.op_kwargs)
           ^^^^^^^^^^^^^^^^^^^^^^^^^^^^^^^^^^^^^^^^^^^
  File "/home/airflow/.local/lib/python3.12/site-packages/airflow/utils/operator_helpers.py", line 252, in run
    return self.func(*args, **kwargs)
           ^^^^^^^^^^^^^^^^^^^^^^^^^^
  File "/opt/airflow/dags/instacart_etl_dag.py", line 88, in etl_dim_table
    cursor.executemany(f"""
pyodbc.ProgrammingError: The second parameter to executemany must not be empty.
[2024-12-17T23:59:54.195+0000] {local_task_job_runner.py:266} INFO - Task exited with return code 1
[2024-12-17T23:59:54.228+0000] {taskinstance.py:3895} INFO - 0 downstream tasks scheduled from follow-on schedule check
[2024-12-17T23:59:54.239+0000] {local_task_job_runner.py:245} INFO - ::endgroup::
