[2024-12-05T09:15:53.583+0000] {local_task_job_runner.py:123} INFO - ::group::Pre task execution logs
[2024-12-05T09:15:53.602+0000] {taskinstance.py:2613} INFO - Dependencies all met for dep_context=non-requeueable deps ti=<TaskInstance: instacart_etl_pl.etl_dim_product manual__2024-12-05T09:15:48.487331+00:00 [queued]>
[2024-12-05T09:15:53.613+0000] {taskinstance.py:2613} INFO - Dependencies all met for dep_context=requeueable deps ti=<TaskInstance: instacart_etl_pl.etl_dim_product manual__2024-12-05T09:15:48.487331+00:00 [queued]>
[2024-12-05T09:15:53.614+0000] {taskinstance.py:2866} INFO - Starting attempt 1 of 1
[2024-12-05T09:15:53.632+0000] {taskinstance.py:2889} INFO - Executing <Task(PythonOperator): etl_dim_product> on 2024-12-05 09:15:48.487331+00:00
[2024-12-05T09:15:53.645+0000] {logging_mixin.py:190} WARNING - /home/***/.local/lib/python3.12/site-packages/***/task/task_runner/standard_task_runner.py:70 DeprecationWarning: This process (pid=5246) is multi-threaded, use of fork() may lead to deadlocks in the child.
[2024-12-05T09:15:53.647+0000] {standard_task_runner.py:72} INFO - Started process 5248 to run task
[2024-12-05T09:15:53.645+0000] {standard_task_runner.py:104} INFO - Running: ['***', 'tasks', 'run', 'instacart_etl_pl', 'etl_dim_product', 'manual__2024-12-05T09:15:48.487331+00:00', '--job-id', '442', '--raw', '--subdir', 'DAGS_FOLDER/instacart_etl_dag.py', '--cfg-path', '/tmp/tmpc85gy205']
[2024-12-05T09:15:53.648+0000] {standard_task_runner.py:105} INFO - Job 442: Subtask etl_dim_product
[2024-12-05T09:15:53.763+0000] {task_command.py:467} INFO - Running <TaskInstance: instacart_etl_pl.etl_dim_product manual__2024-12-05T09:15:48.487331+00:00 [running]> on host 58313fa44d8d
[2024-12-05T09:15:53.869+0000] {taskinstance.py:3132} INFO - Exporting env vars: AIRFLOW_CTX_DAG_OWNER='***' AIRFLOW_CTX_DAG_ID='instacart_etl_pl' AIRFLOW_CTX_TASK_ID='etl_dim_product' AIRFLOW_CTX_EXECUTION_DATE='2024-12-05T09:15:48.487331+00:00' AIRFLOW_CTX_TRY_NUMBER='1' AIRFLOW_CTX_DAG_RUN_ID='manual__2024-12-05T09:15:48.487331+00:00'
[2024-12-05T09:15:53.873+0000] {taskinstance.py:731} INFO - ::endgroup::
[2024-12-05T09:15:53.904+0000] {base.py:84} INFO - Retrieving connection 'mssql_default'
[2024-12-05T09:15:54.164+0000] {taskinstance.py:3311} ERROR - Task failed with exception
Traceback (most recent call last):
  File "src/pymssql/_pymssql.pyx", line 447, in pymssql._pymssql.Cursor.execute
  File "src/pymssql/_mssql.pyx", line 1125, in pymssql._mssql.MSSQLConnection.execute_query
  File "src/pymssql/_mssql.pyx", line 1156, in pymssql._mssql.MSSQLConnection.execute_query
  File "src/pymssql/_mssql.pyx", line 1289, in pymssql._mssql.MSSQLConnection.format_and_run_query
  File "src/pymssql/_mssql.pyx", line 1855, in pymssql._mssql.check_cancel_and_raise
  File "src/pymssql/_mssql.pyx", line 1901, in pymssql._mssql.raise_MSSQLDatabaseException
pymssql._mssql.MSSQLDatabaseException: (206, b'Operand type clash: int is incompatible with datetime2DB-Lib error message 20018, severity 16:\nGeneral SQL Server error: Check messages from the SQL Server\n')

During handling of the above exception, another exception occurred:

Traceback (most recent call last):
  File "/home/airflow/.local/lib/python3.12/site-packages/airflow/models/taskinstance.py", line 767, in _execute_task
    result = _execute_callable(context=context, **execute_callable_kwargs)
             ^^^^^^^^^^^^^^^^^^^^^^^^^^^^^^^^^^^^^^^^^^^^^^^^^^^^^^^^^^^^^
  File "/home/airflow/.local/lib/python3.12/site-packages/airflow/models/taskinstance.py", line 733, in _execute_callable
    return ExecutionCallableRunner(
           ^^^^^^^^^^^^^^^^^^^^^^^^
  File "/home/airflow/.local/lib/python3.12/site-packages/airflow/utils/operator_helpers.py", line 252, in run
    return self.func(*args, **kwargs)
           ^^^^^^^^^^^^^^^^^^^^^^^^^^
  File "/home/airflow/.local/lib/python3.12/site-packages/airflow/models/baseoperator.py", line 417, in wrapper
    return func(self, *args, **kwargs)
           ^^^^^^^^^^^^^^^^^^^^^^^^^^^
  File "/home/airflow/.local/lib/python3.12/site-packages/airflow/operators/python.py", line 238, in execute
    return_value = self.execute_callable()
                   ^^^^^^^^^^^^^^^^^^^^^^^
  File "/home/airflow/.local/lib/python3.12/site-packages/airflow/operators/python.py", line 256, in execute_callable
    return runner.run(*self.op_args, **self.op_kwargs)
           ^^^^^^^^^^^^^^^^^^^^^^^^^^^^^^^^^^^^^^^^^^^
  File "/home/airflow/.local/lib/python3.12/site-packages/airflow/utils/operator_helpers.py", line 252, in run
    return self.func(*args, **kwargs)
           ^^^^^^^^^^^^^^^^^^^^^^^^^^
  File "/opt/airflow/dags/instacart_etl_dag.py", line 83, in etl_dim_table
    cursor.execute(f"""
  File "src/pymssql/_pymssql.pyx", line 465, in pymssql._pymssql.Cursor.execute
pymssql.exceptions.OperationalError: (206, b'Operand type clash: int is incompatible with datetime2DB-Lib error message 20018, severity 16:\nGeneral SQL Server error: Check messages from the SQL Server\n')
[2024-12-05T09:15:54.182+0000] {taskinstance.py:1225} INFO - Marking task as FAILED. dag_id=instacart_etl_pl, task_id=etl_dim_product, run_id=manual__2024-12-05T09:15:48.487331+00:00, execution_date=20241205T091548, start_date=20241205T091553, end_date=20241205T091554
[2024-12-05T09:15:54.197+0000] {taskinstance.py:340} INFO - ::group::Post task execution logs
[2024-12-05T09:15:54.198+0000] {standard_task_runner.py:124} ERROR - Failed to execute job 442 for task etl_dim_product ((206, b'Operand type clash: int is incompatible with datetime2DB-Lib error message 20018, severity 16:\nGeneral SQL Server error: Check messages from the SQL Server\n'); 5248)
Traceback (most recent call last):
  File "src/pymssql/_pymssql.pyx", line 447, in pymssql._pymssql.Cursor.execute
  File "src/pymssql/_mssql.pyx", line 1125, in pymssql._mssql.MSSQLConnection.execute_query
  File "src/pymssql/_mssql.pyx", line 1156, in pymssql._mssql.MSSQLConnection.execute_query
  File "src/pymssql/_mssql.pyx", line 1289, in pymssql._mssql.MSSQLConnection.format_and_run_query
  File "src/pymssql/_mssql.pyx", line 1855, in pymssql._mssql.check_cancel_and_raise
  File "src/pymssql/_mssql.pyx", line 1901, in pymssql._mssql.raise_MSSQLDatabaseException
pymssql._mssql.MSSQLDatabaseException: (206, b'Operand type clash: int is incompatible with datetime2DB-Lib error message 20018, severity 16:\nGeneral SQL Server error: Check messages from the SQL Server\n')

During handling of the above exception, another exception occurred:

Traceback (most recent call last):
  File "/home/airflow/.local/lib/python3.12/site-packages/airflow/task/task_runner/standard_task_runner.py", line 117, in _start_by_fork
    ret = args.func(args, dag=self.dag)
          ^^^^^^^^^^^^^^^^^^^^^^^^^^^^^
  File "/home/airflow/.local/lib/python3.12/site-packages/airflow/cli/cli_config.py", line 49, in command
    return func(*args, **kwargs)
           ^^^^^^^^^^^^^^^^^^^^^
  File "/home/airflow/.local/lib/python3.12/site-packages/airflow/utils/cli.py", line 116, in wrapper
    return f(*args, **kwargs)
           ^^^^^^^^^^^^^^^^^^
  File "/home/airflow/.local/lib/python3.12/site-packages/airflow/cli/commands/task_command.py", line 483, in task_run
    task_return_code = _run_task_by_selected_method(args, _dag, ti)
                       ^^^^^^^^^^^^^^^^^^^^^^^^^^^^^^^^^^^^^^^^^^^^
  File "/home/airflow/.local/lib/python3.12/site-packages/airflow/cli/commands/task_command.py", line 256, in _run_task_by_selected_method
    return _run_raw_task(args, ti)
           ^^^^^^^^^^^^^^^^^^^^^^^
  File "/home/airflow/.local/lib/python3.12/site-packages/airflow/cli/commands/task_command.py", line 341, in _run_raw_task
    return ti._run_raw_task(
           ^^^^^^^^^^^^^^^^^
  File "/home/airflow/.local/lib/python3.12/site-packages/airflow/utils/session.py", line 97, in wrapper
    return func(*args, session=session, **kwargs)
           ^^^^^^^^^^^^^^^^^^^^^^^^^^^^^^^^^^^^^^
  File "/home/airflow/.local/lib/python3.12/site-packages/airflow/models/taskinstance.py", line 3005, in _run_raw_task
    return _run_raw_task(
           ^^^^^^^^^^^^^^
  File "/home/airflow/.local/lib/python3.12/site-packages/airflow/models/taskinstance.py", line 273, in _run_raw_task
    TaskInstance._execute_task_with_callbacks(
  File "/home/airflow/.local/lib/python3.12/site-packages/airflow/models/taskinstance.py", line 3159, in _execute_task_with_callbacks
    result = self._execute_task(context, task_orig)
             ^^^^^^^^^^^^^^^^^^^^^^^^^^^^^^^^^^^^^^
  File "/home/airflow/.local/lib/python3.12/site-packages/airflow/models/taskinstance.py", line 3183, in _execute_task
    return _execute_task(self, context, task_orig)
           ^^^^^^^^^^^^^^^^^^^^^^^^^^^^^^^^^^^^^^^
  File "/home/airflow/.local/lib/python3.12/site-packages/airflow/models/taskinstance.py", line 767, in _execute_task
    result = _execute_callable(context=context, **execute_callable_kwargs)
             ^^^^^^^^^^^^^^^^^^^^^^^^^^^^^^^^^^^^^^^^^^^^^^^^^^^^^^^^^^^^^
  File "/home/airflow/.local/lib/python3.12/site-packages/airflow/models/taskinstance.py", line 733, in _execute_callable
    return ExecutionCallableRunner(
           ^^^^^^^^^^^^^^^^^^^^^^^^
  File "/home/airflow/.local/lib/python3.12/site-packages/airflow/utils/operator_helpers.py", line 252, in run
    return self.func(*args, **kwargs)
           ^^^^^^^^^^^^^^^^^^^^^^^^^^
  File "/home/airflow/.local/lib/python3.12/site-packages/airflow/models/baseoperator.py", line 417, in wrapper
    return func(self, *args, **kwargs)
           ^^^^^^^^^^^^^^^^^^^^^^^^^^^
  File "/home/airflow/.local/lib/python3.12/site-packages/airflow/operators/python.py", line 238, in execute
    return_value = self.execute_callable()
                   ^^^^^^^^^^^^^^^^^^^^^^^
  File "/home/airflow/.local/lib/python3.12/site-packages/airflow/operators/python.py", line 256, in execute_callable
    return runner.run(*self.op_args, **self.op_kwargs)
           ^^^^^^^^^^^^^^^^^^^^^^^^^^^^^^^^^^^^^^^^^^^
  File "/home/airflow/.local/lib/python3.12/site-packages/airflow/utils/operator_helpers.py", line 252, in run
    return self.func(*args, **kwargs)
           ^^^^^^^^^^^^^^^^^^^^^^^^^^
  File "/opt/airflow/dags/instacart_etl_dag.py", line 83, in etl_dim_table
    cursor.execute(f"""
  File "src/pymssql/_pymssql.pyx", line 465, in pymssql._pymssql.Cursor.execute
pymssql.exceptions.OperationalError: (206, b'Operand type clash: int is incompatible with datetime2DB-Lib error message 20018, severity 16:\nGeneral SQL Server error: Check messages from the SQL Server\n')
[2024-12-05T09:15:54.223+0000] {local_task_job_runner.py:266} INFO - Task exited with return code 1
[2024-12-05T09:15:54.280+0000] {taskinstance.py:3895} INFO - 0 downstream tasks scheduled from follow-on schedule check
[2024-12-05T09:15:54.284+0000] {local_task_job_runner.py:245} INFO - ::endgroup::
