[2024-12-12T15:36:37.956+0000] {local_task_job_runner.py:123} INFO - ::group::Pre task execution logs
[2024-12-12T15:36:37.979+0000] {taskinstance.py:2613} INFO - Dependencies all met for dep_context=non-requeueable deps ti=<TaskInstance: etl_test.etl_dim_user manual__2024-12-12T15:36:35.195173+00:00 [queued]>
[2024-12-12T15:36:37.991+0000] {taskinstance.py:2613} INFO - Dependencies all met for dep_context=requeueable deps ti=<TaskInstance: etl_test.etl_dim_user manual__2024-12-12T15:36:35.195173+00:00 [queued]>
[2024-12-12T15:36:37.992+0000] {taskinstance.py:2866} INFO - Starting attempt 1 of 1
[2024-12-12T15:36:38.009+0000] {taskinstance.py:2889} INFO - Executing <Task(PythonOperator): etl_dim_user> on 2024-12-12 15:36:35.195173+00:00
[2024-12-12T15:36:38.020+0000] {warnings.py:112} WARNING - /home/***/.local/lib/python3.12/site-packages/***/task/task_runner/standard_task_runner.py:70: DeprecationWarning: This process (pid=111) is multi-threaded, use of fork() may lead to deadlocks in the child.
  pid = os.fork()

[2024-12-12T15:36:38.023+0000] {standard_task_runner.py:72} INFO - Started process 113 to run task
[2024-12-12T15:36:38.021+0000] {standard_task_runner.py:104} INFO - Running: ['***', 'tasks', 'run', 'etl_test', 'etl_dim_user', 'manual__2024-12-12T15:36:35.195173+00:00', '--job-id', '310', '--raw', '--subdir', 'DAGS_FOLDER/test_etl_dag.py', '--cfg-path', '/tmp/tmpehw3xpuf']
[2024-12-12T15:36:38.024+0000] {standard_task_runner.py:105} INFO - Job 310: Subtask etl_dim_user
[2024-12-12T15:36:38.085+0000] {task_command.py:467} INFO - Running <TaskInstance: etl_test.etl_dim_user manual__2024-12-12T15:36:35.195173+00:00 [running]> on host dd4005ca4c89
[2024-12-12T15:36:39.960+0000] {taskinstance.py:3132} INFO - Exporting env vars: AIRFLOW_CTX_DAG_OWNER='***' AIRFLOW_CTX_DAG_ID='etl_test' AIRFLOW_CTX_TASK_ID='etl_dim_user' AIRFLOW_CTX_EXECUTION_DATE='2024-12-12T15:36:35.195173+00:00' AIRFLOW_CTX_TRY_NUMBER='1' AIRFLOW_CTX_DAG_RUN_ID='manual__2024-12-12T15:36:35.195173+00:00'
[2024-12-12T15:36:39.972+0000] {taskinstance.py:731} INFO - ::endgroup::
[2024-12-12T15:36:40.429+0000] {base.py:84} INFO - Retrieving connection 'mssql_default'
[2024-12-12T15:37:04.353+0000] {taskinstance.py:3311} ERROR - Task failed with exception
Traceback (most recent call last):
  File "src/pymssql/_pymssql.pyx", line 650, in pymssql._pymssql.connect
  File "src/pymssql/_mssql.pyx", line 2158, in pymssql._mssql.connect
  File "src/pymssql/_mssql.pyx", line 712, in pymssql._mssql.MSSQLConnection.__init__
  File "src/pymssql/_mssql.pyx", line 1884, in pymssql._mssql.maybe_raise_MSSQLDatabaseException
  File "src/pymssql/_mssql.pyx", line 1901, in pymssql._mssql.raise_MSSQLDatabaseException
pymssql._mssql.MSSQLDatabaseException: (20009, b'DB-Lib error message 20009, severity 9:\nUnable to connect: Adaptive Server is unavailable or does not exist (sqlserver)\nNet-Lib error during Connection refused (111)\nDB-Lib error message 20009, severity 9:\nUnable to connect: Adaptive Server is unavailable or does not exist (sqlserver)\nNet-Lib error during Connection refused (111)\n')

During handling of the above exception, another exception occurred:

Traceback (most recent call last):
  File "/home/airflow/.local/lib/python3.12/site-packages/airflow/models/taskinstance.py", line 767, in _execute_task
    result = _execute_callable(context=context, **execute_callable_kwargs)
             ^^^^^^^^^^^^^^^^^^^^^^^^^^^^^^^^^^^^^^^^^^^^^^^^^^^^^^^^^^^^^
  File "/home/airflow/.local/lib/python3.12/site-packages/airflow/models/taskinstance.py", line 733, in _execute_callable
    return ExecutionCallableRunner(
           ^^^^^^^^^^^^^^^^^^^^^^^^
  File "/home/airflow/.local/lib/python3.12/site-packages/airflow/utils/operator_helpers.py", line 252, in run
    return self.func(*args, **kwargs)
           ^^^^^^^^^^^^^^^^^^^^^^^^^^
  File "/home/airflow/.local/lib/python3.12/site-packages/airflow/models/baseoperator.py", line 417, in wrapper
    return func(self, *args, **kwargs)
           ^^^^^^^^^^^^^^^^^^^^^^^^^^^
  File "/home/airflow/.local/lib/python3.12/site-packages/airflow/operators/python.py", line 238, in execute
    return_value = self.execute_callable()
                   ^^^^^^^^^^^^^^^^^^^^^^^
  File "/home/airflow/.local/lib/python3.12/site-packages/airflow/operators/python.py", line 256, in execute_callable
    return runner.run(*self.op_args, **self.op_kwargs)
           ^^^^^^^^^^^^^^^^^^^^^^^^^^^^^^^^^^^^^^^^^^^
  File "/home/airflow/.local/lib/python3.12/site-packages/airflow/utils/operator_helpers.py", line 252, in run
    return self.func(*args, **kwargs)
           ^^^^^^^^^^^^^^^^^^^^^^^^^^
  File "/opt/airflow/dags/test_etl_dag.py", line 44, in etl_dim_user
    conn = mssql_hook.get_conn()
           ^^^^^^^^^^^^^^^^^^^^^
  File "/home/airflow/.local/lib/python3.12/site-packages/airflow/providers/microsoft/mssql/hooks/mssql.py", line 140, in get_conn
    return pymssql.connect(
           ^^^^^^^^^^^^^^^^
  File "src/pymssql/_pymssql.pyx", line 659, in pymssql._pymssql.connect
pymssql.exceptions.OperationalError: (20009, b'DB-Lib error message 20009, severity 9:\nUnable to connect: Adaptive Server is unavailable or does not exist (sqlserver)\nNet-Lib error during Connection refused (111)\nDB-Lib error message 20009, severity 9:\nUnable to connect: Adaptive Server is unavailable or does not exist (sqlserver)\nNet-Lib error during Connection refused (111)\n')
[2024-12-12T15:37:05.245+0000] {taskinstance.py:1225} INFO - Marking task as FAILED. dag_id=etl_test, task_id=etl_dim_user, run_id=manual__2024-12-12T15:36:35.195173+00:00, execution_date=20241212T153635, start_date=20241212T153637, end_date=20241212T153705
[2024-12-12T15:37:05.245+0000] {job.py:229} INFO - Heartbeat recovered after 27.39 seconds
[2024-12-12T15:37:05.309+0000] {taskinstance.py:340} INFO - ::group::Post task execution logs
[2024-12-12T15:37:05.311+0000] {standard_task_runner.py:124} ERROR - Failed to execute job 310 for task etl_dim_user ((20009, b'DB-Lib error message 20009, severity 9:\nUnable to connect: Adaptive Server is unavailable or does not exist (sqlserver)\nNet-Lib error during Connection refused (111)\nDB-Lib error message 20009, severity 9:\nUnable to connect: Adaptive Server is unavailable or does not exist (sqlserver)\nNet-Lib error during Connection refused (111)\n'); 113)
Traceback (most recent call last):
  File "src/pymssql/_pymssql.pyx", line 650, in pymssql._pymssql.connect
  File "src/pymssql/_mssql.pyx", line 2158, in pymssql._mssql.connect
  File "src/pymssql/_mssql.pyx", line 712, in pymssql._mssql.MSSQLConnection.__init__
  File "src/pymssql/_mssql.pyx", line 1884, in pymssql._mssql.maybe_raise_MSSQLDatabaseException
  File "src/pymssql/_mssql.pyx", line 1901, in pymssql._mssql.raise_MSSQLDatabaseException
pymssql._mssql.MSSQLDatabaseException: (20009, b'DB-Lib error message 20009, severity 9:\nUnable to connect: Adaptive Server is unavailable or does not exist (sqlserver)\nNet-Lib error during Connection refused (111)\nDB-Lib error message 20009, severity 9:\nUnable to connect: Adaptive Server is unavailable or does not exist (sqlserver)\nNet-Lib error during Connection refused (111)\n')

During handling of the above exception, another exception occurred:

Traceback (most recent call last):
  File "/home/airflow/.local/lib/python3.12/site-packages/airflow/task/task_runner/standard_task_runner.py", line 117, in _start_by_fork
    ret = args.func(args, dag=self.dag)
          ^^^^^^^^^^^^^^^^^^^^^^^^^^^^^
  File "/home/airflow/.local/lib/python3.12/site-packages/airflow/cli/cli_config.py", line 49, in command
    return func(*args, **kwargs)
           ^^^^^^^^^^^^^^^^^^^^^
  File "/home/airflow/.local/lib/python3.12/site-packages/airflow/utils/cli.py", line 116, in wrapper
    return f(*args, **kwargs)
           ^^^^^^^^^^^^^^^^^^
  File "/home/airflow/.local/lib/python3.12/site-packages/airflow/cli/commands/task_command.py", line 483, in task_run
    task_return_code = _run_task_by_selected_method(args, _dag, ti)
                       ^^^^^^^^^^^^^^^^^^^^^^^^^^^^^^^^^^^^^^^^^^^^
  File "/home/airflow/.local/lib/python3.12/site-packages/airflow/cli/commands/task_command.py", line 256, in _run_task_by_selected_method
    return _run_raw_task(args, ti)
           ^^^^^^^^^^^^^^^^^^^^^^^
  File "/home/airflow/.local/lib/python3.12/site-packages/airflow/cli/commands/task_command.py", line 341, in _run_raw_task
    return ti._run_raw_task(
           ^^^^^^^^^^^^^^^^^
  File "/home/airflow/.local/lib/python3.12/site-packages/airflow/utils/session.py", line 97, in wrapper
    return func(*args, session=session, **kwargs)
           ^^^^^^^^^^^^^^^^^^^^^^^^^^^^^^^^^^^^^^
  File "/home/airflow/.local/lib/python3.12/site-packages/airflow/models/taskinstance.py", line 3005, in _run_raw_task
    return _run_raw_task(
           ^^^^^^^^^^^^^^
  File "/home/airflow/.local/lib/python3.12/site-packages/airflow/models/taskinstance.py", line 273, in _run_raw_task
    TaskInstance._execute_task_with_callbacks(
  File "/home/airflow/.local/lib/python3.12/site-packages/airflow/models/taskinstance.py", line 3159, in _execute_task_with_callbacks
    result = self._execute_task(context, task_orig)
             ^^^^^^^^^^^^^^^^^^^^^^^^^^^^^^^^^^^^^^
  File "/home/airflow/.local/lib/python3.12/site-packages/airflow/models/taskinstance.py", line 3183, in _execute_task
    return _execute_task(self, context, task_orig)
           ^^^^^^^^^^^^^^^^^^^^^^^^^^^^^^^^^^^^^^^
  File "/home/airflow/.local/lib/python3.12/site-packages/airflow/models/taskinstance.py", line 767, in _execute_task
    result = _execute_callable(context=context, **execute_callable_kwargs)
             ^^^^^^^^^^^^^^^^^^^^^^^^^^^^^^^^^^^^^^^^^^^^^^^^^^^^^^^^^^^^^
  File "/home/airflow/.local/lib/python3.12/site-packages/airflow/models/taskinstance.py", line 733, in _execute_callable
    return ExecutionCallableRunner(
           ^^^^^^^^^^^^^^^^^^^^^^^^
  File "/home/airflow/.local/lib/python3.12/site-packages/airflow/utils/operator_helpers.py", line 252, in run
    return self.func(*args, **kwargs)
           ^^^^^^^^^^^^^^^^^^^^^^^^^^
  File "/home/airflow/.local/lib/python3.12/site-packages/airflow/models/baseoperator.py", line 417, in wrapper
    return func(self, *args, **kwargs)
           ^^^^^^^^^^^^^^^^^^^^^^^^^^^
  File "/home/airflow/.local/lib/python3.12/site-packages/airflow/operators/python.py", line 238, in execute
    return_value = self.execute_callable()
                   ^^^^^^^^^^^^^^^^^^^^^^^
  File "/home/airflow/.local/lib/python3.12/site-packages/airflow/operators/python.py", line 256, in execute_callable
    return runner.run(*self.op_args, **self.op_kwargs)
           ^^^^^^^^^^^^^^^^^^^^^^^^^^^^^^^^^^^^^^^^^^^
  File "/home/airflow/.local/lib/python3.12/site-packages/airflow/utils/operator_helpers.py", line 252, in run
    return self.func(*args, **kwargs)
           ^^^^^^^^^^^^^^^^^^^^^^^^^^
  File "/opt/airflow/dags/test_etl_dag.py", line 44, in etl_dim_user
    conn = mssql_hook.get_conn()
           ^^^^^^^^^^^^^^^^^^^^^
  File "/home/airflow/.local/lib/python3.12/site-packages/airflow/providers/microsoft/mssql/hooks/mssql.py", line 140, in get_conn
    return pymssql.connect(
           ^^^^^^^^^^^^^^^^
  File "src/pymssql/_pymssql.pyx", line 659, in pymssql._pymssql.connect
pymssql.exceptions.OperationalError: (20009, b'DB-Lib error message 20009, severity 9:\nUnable to connect: Adaptive Server is unavailable or does not exist (sqlserver)\nNet-Lib error during Connection refused (111)\nDB-Lib error message 20009, severity 9:\nUnable to connect: Adaptive Server is unavailable or does not exist (sqlserver)\nNet-Lib error during Connection refused (111)\n')
[2024-12-12T15:37:05.380+0000] {local_task_job_runner.py:266} INFO - Task exited with return code 1
[2024-12-12T15:37:06.228+0000] {taskinstance.py:3895} INFO - 0 downstream tasks scheduled from follow-on schedule check
[2024-12-12T15:37:06.239+0000] {local_task_job_runner.py:245} INFO - ::endgroup::
