[2024-12-17T15:01:49.576+0000] {local_task_job_runner.py:123} INFO - ::group::Pre task execution logs
[2024-12-17T15:01:49.678+0000] {taskinstance.py:2613} INFO - Dependencies all met for dep_context=non-requeueable deps ti=<TaskInstance: instacart_etl.etl_dim_order_products manual__2024-12-17T14:32:27.126134+00:00 [queued]>
[2024-12-17T15:01:49.709+0000] {taskinstance.py:2613} INFO - Dependencies all met for dep_context=requeueable deps ti=<TaskInstance: instacart_etl.etl_dim_order_products manual__2024-12-17T14:32:27.126134+00:00 [queued]>
[2024-12-17T15:01:49.710+0000] {taskinstance.py:2866} INFO - Starting attempt 2 of 2
[2024-12-17T15:01:49.756+0000] {taskinstance.py:2889} INFO - Executing <Task(PythonOperator): etl_dim_order_products> on 2024-12-17 14:32:27.126134+00:00
[2024-12-17T15:01:49.804+0000] {logging_mixin.py:190} WARNING - /home/***/.local/lib/python3.12/site-packages/***/task/task_runner/standard_task_runner.py:70 DeprecationWarning: This process (pid=12301) is multi-threaded, use of fork() may lead to deadlocks in the child.
[2024-12-17T15:01:49.808+0000] {standard_task_runner.py:72} INFO - Started process 12303 to run task
[2024-12-17T15:01:49.862+0000] {standard_task_runner.py:104} INFO - Running: ['***', 'tasks', 'run', 'instacart_etl', 'etl_dim_order_products', 'manual__2024-12-17T14:32:27.126134+00:00', '--job-id', '62', '--raw', '--subdir', 'DAGS_FOLDER/instacart_etl_dag.py', '--cfg-path', '/tmp/tmpr5t0xqc_']
[2024-12-17T15:01:49.897+0000] {standard_task_runner.py:105} INFO - Job 62: Subtask etl_dim_order_products
[2024-12-17T15:01:50.111+0000] {task_command.py:467} INFO - Running <TaskInstance: instacart_etl.etl_dim_order_products manual__2024-12-17T14:32:27.126134+00:00 [running]> on host ad3472fa3861
[2024-12-17T15:01:50.314+0000] {taskinstance.py:3132} INFO - Exporting env vars: AIRFLOW_CTX_DAG_OWNER='***' AIRFLOW_CTX_DAG_ID='instacart_etl' AIRFLOW_CTX_TASK_ID='etl_dim_order_products' AIRFLOW_CTX_EXECUTION_DATE='2024-12-17T14:32:27.126134+00:00' AIRFLOW_CTX_TRY_NUMBER='2' AIRFLOW_CTX_DAG_RUN_ID='manual__2024-12-17T14:32:27.126134+00:00'
[2024-12-17T15:01:50.316+0000] {taskinstance.py:731} INFO - ::endgroup::
[2024-12-17T15:23:33.915+0000] {local_task_job_runner.py:346} WARNING - State of this instance has been externally set to removed. Terminating instance.
[2024-12-17T15:23:34.000+0000] {local_task_job_runner.py:245} INFO - ::endgroup::
[2024-12-17T15:23:34.013+0000] {process_utils.py:132} INFO - Sending 15 to group 12303. PIDs of all processes in the group: [12303]
[2024-12-17T15:23:34.017+0000] {process_utils.py:87} INFO - Sending the signal 15 to group 12303
[2024-12-17T15:23:34.036+0000] {taskinstance.py:3093} ERROR - Received SIGTERM. Terminating subprocesses.
[2024-12-17T15:23:34.120+0000] {taskinstance.py:3311} ERROR - Task failed with exception
Traceback (most recent call last):
  File "/usr/local/lib/python3.12/encodings/utf_16_le.py", line 15, in decode
    def decode(input, errors='strict'):
    
  File "/home/airflow/.local/lib/python3.12/site-packages/airflow/models/taskinstance.py", line 3095, in signal_handler
    raise AirflowTaskTerminated("Task received SIGTERM signal")
airflow.exceptions.AirflowTaskTerminated: Task received SIGTERM signal
decoding with 'utf-16le' codec failed

The above exception was the direct cause of the following exception:

Traceback (most recent call last):
  File "/home/airflow/.local/lib/python3.12/site-packages/airflow/models/taskinstance.py", line 767, in _execute_task
    result = _execute_callable(context=context, **execute_callable_kwargs)
             ^^^^^^^^^^^^^^^^^^^^^^^^^^^^^^^^^^^^^^^^^^^^^^^^^^^^^^^^^^^^^
  File "/home/airflow/.local/lib/python3.12/site-packages/airflow/models/taskinstance.py", line 733, in _execute_callable
    return ExecutionCallableRunner(
           ^^^^^^^^^^^^^^^^^^^^^^^^
  File "/home/airflow/.local/lib/python3.12/site-packages/airflow/utils/operator_helpers.py", line 252, in run
    return self.func(*args, **kwargs)
           ^^^^^^^^^^^^^^^^^^^^^^^^^^
  File "/home/airflow/.local/lib/python3.12/site-packages/airflow/models/baseoperator.py", line 417, in wrapper
    return func(self, *args, **kwargs)
           ^^^^^^^^^^^^^^^^^^^^^^^^^^^
  File "/home/airflow/.local/lib/python3.12/site-packages/airflow/operators/python.py", line 238, in execute
    return_value = self.execute_callable()
                   ^^^^^^^^^^^^^^^^^^^^^^^
  File "/home/airflow/.local/lib/python3.12/site-packages/airflow/operators/python.py", line 256, in execute_callable
    return runner.run(*self.op_args, **self.op_kwargs)
           ^^^^^^^^^^^^^^^^^^^^^^^^^^^^^^^^^^^^^^^^^^^
  File "/home/airflow/.local/lib/python3.12/site-packages/airflow/utils/operator_helpers.py", line 252, in run
    return self.func(*args, **kwargs)
           ^^^^^^^^^^^^^^^^^^^^^^^^^^
  File "/opt/airflow/dags/instacart_etl_dag.py", line 221, in etl_dim_order_products
    cursor.close()
            ^^^^^^
SystemError: <class 'pyodbc.Error'> returned a result with an exception set
[2024-12-17T15:23:34.325+0000] {taskinstance.py:1225} INFO - Marking task as FAILED. dag_id=instacart_etl, task_id=etl_dim_order_products, run_id=manual__2024-12-17T14:32:27.126134+00:00, execution_date=20241217T143227, start_date=20241217T150149, end_date=20241217T152334
[2024-12-17T15:23:34.452+0000] {taskinstance.py:340} INFO - ::group::Post task execution logs
[2024-12-17T15:23:34.461+0000] {standard_task_runner.py:124} ERROR - Failed to execute job 62 for task etl_dim_order_products (<class 'pyodbc.Error'> returned a result with an exception set; 12303)
Traceback (most recent call last):
  File "/usr/local/lib/python3.12/encodings/utf_16_le.py", line 15, in decode
    def decode(input, errors='strict'):
    
  File "/home/airflow/.local/lib/python3.12/site-packages/airflow/models/taskinstance.py", line 3095, in signal_handler
    raise AirflowTaskTerminated("Task received SIGTERM signal")
airflow.exceptions.AirflowTaskTerminated: Task received SIGTERM signal
decoding with 'utf-16le' codec failed

The above exception was the direct cause of the following exception:

Traceback (most recent call last):
  File "/home/airflow/.local/lib/python3.12/site-packages/airflow/task/task_runner/standard_task_runner.py", line 117, in _start_by_fork
    ret = args.func(args, dag=self.dag)
          ^^^^^^^^^^^^^^^^^^^^^^^^^^^^^
  File "/home/airflow/.local/lib/python3.12/site-packages/airflow/cli/cli_config.py", line 49, in command
    return func(*args, **kwargs)
           ^^^^^^^^^^^^^^^^^^^^^
  File "/home/airflow/.local/lib/python3.12/site-packages/airflow/utils/cli.py", line 116, in wrapper
    return f(*args, **kwargs)
           ^^^^^^^^^^^^^^^^^^
  File "/home/airflow/.local/lib/python3.12/site-packages/airflow/cli/commands/task_command.py", line 483, in task_run
    task_return_code = _run_task_by_selected_method(args, _dag, ti)
                       ^^^^^^^^^^^^^^^^^^^^^^^^^^^^^^^^^^^^^^^^^^^^
  File "/home/airflow/.local/lib/python3.12/site-packages/airflow/cli/commands/task_command.py", line 256, in _run_task_by_selected_method
    return _run_raw_task(args, ti)
           ^^^^^^^^^^^^^^^^^^^^^^^
  File "/home/airflow/.local/lib/python3.12/site-packages/airflow/cli/commands/task_command.py", line 341, in _run_raw_task
    return ti._run_raw_task(
           ^^^^^^^^^^^^^^^^^
  File "/home/airflow/.local/lib/python3.12/site-packages/airflow/utils/session.py", line 97, in wrapper
    return func(*args, session=session, **kwargs)
           ^^^^^^^^^^^^^^^^^^^^^^^^^^^^^^^^^^^^^^
  File "/home/airflow/.local/lib/python3.12/site-packages/airflow/models/taskinstance.py", line 3005, in _run_raw_task
    return _run_raw_task(
           ^^^^^^^^^^^^^^
  File "/home/airflow/.local/lib/python3.12/site-packages/airflow/models/taskinstance.py", line 273, in _run_raw_task
    TaskInstance._execute_task_with_callbacks(
  File "/home/airflow/.local/lib/python3.12/site-packages/airflow/models/taskinstance.py", line 3159, in _execute_task_with_callbacks
    result = self._execute_task(context, task_orig)
             ^^^^^^^^^^^^^^^^^^^^^^^^^^^^^^^^^^^^^^
  File "/home/airflow/.local/lib/python3.12/site-packages/airflow/models/taskinstance.py", line 3183, in _execute_task
    return _execute_task(self, context, task_orig)
           ^^^^^^^^^^^^^^^^^^^^^^^^^^^^^^^^^^^^^^^
  File "/home/airflow/.local/lib/python3.12/site-packages/airflow/models/taskinstance.py", line 767, in _execute_task
    result = _execute_callable(context=context, **execute_callable_kwargs)
             ^^^^^^^^^^^^^^^^^^^^^^^^^^^^^^^^^^^^^^^^^^^^^^^^^^^^^^^^^^^^^
  File "/home/airflow/.local/lib/python3.12/site-packages/airflow/models/taskinstance.py", line 733, in _execute_callable
    return ExecutionCallableRunner(
           ^^^^^^^^^^^^^^^^^^^^^^^^
  File "/home/airflow/.local/lib/python3.12/site-packages/airflow/utils/operator_helpers.py", line 252, in run
    return self.func(*args, **kwargs)
           ^^^^^^^^^^^^^^^^^^^^^^^^^^
  File "/home/airflow/.local/lib/python3.12/site-packages/airflow/models/baseoperator.py", line 417, in wrapper
    return func(self, *args, **kwargs)
           ^^^^^^^^^^^^^^^^^^^^^^^^^^^
  File "/home/airflow/.local/lib/python3.12/site-packages/airflow/operators/python.py", line 238, in execute
    return_value = self.execute_callable()
                   ^^^^^^^^^^^^^^^^^^^^^^^
  File "/home/airflow/.local/lib/python3.12/site-packages/airflow/operators/python.py", line 256, in execute_callable
    return runner.run(*self.op_args, **self.op_kwargs)
           ^^^^^^^^^^^^^^^^^^^^^^^^^^^^^^^^^^^^^^^^^^^
  File "/home/airflow/.local/lib/python3.12/site-packages/airflow/utils/operator_helpers.py", line 252, in run
    return self.func(*args, **kwargs)
           ^^^^^^^^^^^^^^^^^^^^^^^^^^
  File "/opt/airflow/dags/instacart_etl_dag.py", line 221, in etl_dim_order_products
    cursor.close()
            ^^^^^^
SystemError: <class 'pyodbc.Error'> returned a result with an exception set
[2024-12-17T15:23:34.553+0000] {process_utils.py:80} INFO - Process psutil.Process(pid=12303, status='terminated', exitcode=1, started='15:01:49') (12303) terminated with exit code 1
